<mujoco model="SLIP">
  <compiler inertiafromgeom="false" angle="degree" />
  
  <default>
    <joint limited='true' damping='1' armature='1' />
    <geom contype='7' conaffinity='7' condim='1' rgba='0.8 0.6 .4 1' margin="0.001" solref=".005 1" solimp=".99 .98 .01" material="geom" />
    <motor ctrlrange='-.4 .4' ctrllimited='true' />  
  </default>
  
  <option timestep="0.001" integrator="Euler" gravity="0 0 -9.806"/>
  <asset>
    <texture type="skybox" builtin="gradient" width="100" height="100" rgb1="1 1 1" rgb2="0 0 0" />
    <texture name="texgeom" type="cube" builtin="flat" mark="cross" width="127" height="1278" rgb1="0.8 0.6 0.4" rgb2="0.8 0.6 0.4" markrgb="1 1 1" random="0.01" />
    <texture name="texplane" type="2d" builtin="checker" rgb1="0 0 0" rgb2="0.8 0.8 0.8" width="100" height="100" />
    <material name='MatPlane' texture="texplane" shininess="1" texrepeat="60 60" specular="1"  reflectance="0.5" />
    <material name='geom' texture="texgeom" texuniform="true" />
  </asset>

  <worldbody>
    <light directional="true" cutoff="100" exponent="1" diffuse="1 1 1" specular=".1 .1 .1" pos="0 0 1.3" dir="-0 0 -1.3" />
    <geom name='floor' contype='7' conaffinity='7' pos='0 0 0' size='40 40 40' type='plane' rgba='0.8 0.9 0.8 1' condim='3' friction="2.0" material="MatPlane"/>
    
    <body name="block1" pos="0 0 0.3">
      <joint name='rootx' type='slide' axis='1 0 0' pos='0 0 0' limited='false' damping='0' armature='0' stiffness='0' />
      <joint name='rootz' type='slide' axis='0 0 1' pos='0 0 0' limited='false' damping='0' armature='0' stiffness='0' />
      <geom name="block_geom" type="box" size="0.3 0.3 0.3" friction="0.9"/>
      <inertial pos='0 0 0' mass='10' diaginertia = '0.2 0.2 0.2'/>
      <site name="site1" type="sphere" pos="-0.25 0 -0.3" size="0.015"/>
      <site name="site2" type="sphere" pos="0.25 0 -0.3" size="0.015"/>
    </body> <!--end block 1 -->


  </worldbody>
  
  
</mujoco>