<mujoco model="SLIP">
  <compiler inertiafromgeom="false" angle="degree" />
  
  <default>
    <joint limited='true' damping='1' armature='1' />
    <geom contype='7' conaffinity='7' condim='1' rgba='0.8 0.6 .4 1' margin="0.001" solref=".005 1" solimp=".8 .8 .01" material="geom" />
    <motor ctrlrange='-.4 .4' ctrllimited='true' />  
  </default>
  
  <option timestep="0.001" integrator="Euler" gravity="0 0 -9.806"/>
  <asset>
    <texture type="skybox" builtin="gradient" width="100" height="100" rgb1="1 1 1" rgb2="0 0 0" />
    <texture name="texgeom" type="cube" builtin="flat" mark="cross" width="127" height="1278" rgb1="0.8 0.6 0.4" rgb2="0.8 0.6 0.4" markrgb="1 1 1" random="0.01" />
    <texture name="texplane" type="2d" builtin="checker" rgb1="0 0 0" rgb2="0.8 0.8 0.8" width="100" height="100" />
    <material name='MatPlane' texture="texplane" shininess="1" texrepeat="60 60" specular="1"  reflectance="0.5" />
    <material name='geom' texture="texgeom" texuniform="true" />
  </asset>

  <worldbody>
    <light directional="true" cutoff="100" exponent="1" diffuse="1 1 1" specular=".1 .1 .1" pos="0 0 1.3" dir="-0 0 -1.3" />
    <geom name='floor' contype='7' conaffinity='7' material="MatPlane" pos='0 0 0' size='40 40 40' type='plane' rgba='0.8 0.9 0.8 1' condim='3' friction="2.0" />
    
    <body name="torso" pos="0 0 1.2">
      <joint name='rootx' type='slide' axis='-1 0 0' pos='0 0 0' limited='false' damping='0' armature='0' stiffness='0' />
      <joint name='rootz' type='slide' axis='0 0 1' pos='0 0 0' limited='false' damping='0' armature='0' stiffness='0' ref='1.2'/>
      <joint name='rot' type='hinge' axis='0 -1 0' pos='0 0 0' limited='false' damping='100000' armature='0' stiffness='100000' />
      <geom name="torso_geom" type="sphere" size="0.15" friction="0.9"/>
      <inertial pos='0 0 0' mass='10' diaginertia = '0.2 0.2 0.2'/>

      <body name="leg" pos="0 0 -0.15">
        <joint name='leg_tau' type = 'hinge' axis='0 1 0' pos='0 0 0.15' limited='true' range='-30 30' damping='2' armature='0' stiffness='0' />
        <inertial pos='0 0 -0.1' mass='0.5' diaginertia = '0.01 0.01 0.01'/>
	<joint name='leg_motor' type='slide' axis='0 0 -1' pos='0 0 0' limited='true' range='0.3 0.6' ref='0' damping='10' armature='10' stiffness='0'/>
	<!--I think the range is calculated with respect to parent body, so [-0.4 0] means 0.4 downward from the parent to the parent at 0, if z axis set to -1  -->
<!--joint name='leg_motor' type='slide' axis='0 0 -1' pos='0 0 0' limited='true' range='-0.4 0' damping='0' armature='30' ref='-0.2' stiffness='0'/>  This if for backup-->

	<geom name="leg_geom"  type="capsule" contype='2' conaffinity='2' fromto="0 0 0 0 0 -0.2" size="0.03" friction="0.9" rgba="0.1 0.7 0.2 1" />
	
        <body name="toe" pos="0 0 -0.3">
	    	<joint name='spring' type='slide' axis='0 0 1' pos='0 0 0' limited='true' range='-0.3 0.3' damping='10' armature='0' stiffness='25000'/>
	        <geom type='sphere' size='0.03' pos='0 0 0' friction="0.1" rgba ='0.9 0.5 0.1 1'/>
		<inertial pos='0 0 0' mass='0.15' diaginertia = '0.01 0.01 0.01'/>
		<body name="foot" pos="0 0 -0.05">
            		<joint name="foot_joint" type="hinge" pos="0 0 0" axis="0 -1 0" range="-45 45" armature='0' stiffness='100000' damping='100000'/>
            		<geom name="foot_geom" type="capsule" fromto="-0.1 0 0 0.1 0 0" size="0.02" friction="2.0" />
			<site name="foot_heel" type="sphere" pos="-0.11 0 -0.02" size="0.015"/>
			<site name="foot_toe" type="sphere" pos="0.11 0 -0.02" size="0.015"/>
			<inertial pos='0 0 0' mass='0.15' diaginertia = '0.2 0.2 0.2'/>
          	</body>
        </body>
      </body>
    </body>
  </worldbody>
  
  <actuator>
    <motor joint="leg_tau" ctrlrange="-500.0 500.0" ctrllimited="true" />
    <motor joint="leg_motor" ctrlrange="-2000.0 2000.0" ctrllimited="true" />
    <motor joint="foot_joint" ctrlrange="-500.0 500.0" ctrllimited="true" />
  </actuator>
</mujoco>
